Workbook
Name breaker_info: Breakers!$B$2:$E$45
Name device_wattage: 'Device Wattages'!$A$2:$E$38
Name breaker_boxes: 'Breaker boxes'!$A$2:$C$4

Sheet Update Tracking
A1: Update Date | B1: Version | C1: Comments
A2: 6693056 | B2: 3 | C2: Added Master Bath Hot Tub (theoretically wired to 3 circuits for pump, heater, and blower) However, have not tied to its associated circuits .. And it doesn't matter much since it is no longer in use
A3: 45510 | B3: 2 | C3: Converted Named Ranges to use of Tables (for no good reason) Also cleaned up a few things and added power summary by breaker box
A5: 45300 | B5: 1 | C5: Replaced some hardcoded tables with some base tables and then references to those tables (to maintain a single source for each data tab)
A6: 45411 | B6: 0 | C6: Original Creation
A7: 45690 | B7: 4 | C7: Adding SE light switches in bonus room. Fixing for proper separation with Ceiling Fan and Ceiling Lights
A8: 46099 | B8: 5 | C8: INCOMPLETE NOTES: Waiting for electrician to complete work Fixed room quite a few things, and also noted some power values under Device Wattages (also may want to add a multiplier for some Electrical items that have things like multiple lights on one circuit. Not sure? Added Garage outlets and Bonus room ceiling lights -- Also added more Heat pumps (but they need verified power info)

Sheet Breaker Power Loads
A1: =IFERROR(__xludf.DUMMYFUNCTION("QUERY('Electrical Items'!A1:L179,""SELECT I, H, sum(K) WHERE I='Main' group by I, H order by I, H"",1)"),"Breaker Box") -> Breaker Box | B1: =IFERROR(__xludf.DUMMYFUNCTION("""COMPUTED_VALUE"""),"Breaker") -> Breaker | C1: =IFERROR(__xludf.DUMMYFUNCTION("""COMPUTED_VALUE"""),"sum Power draw") -> sum Power draw | D1: Attached Electrical Items | G1: =IFERROR(__xludf.DUMMYFUNCTION("QUERY('Electrical Items'!G1:R179,""SELECT I, H, sum(K) WHERE I='Utility Subpanel' group by I, H order by I, H"",1)"),"Breaker Box") -> Breaker Box | H1: =IFERROR(__xludf.DUMMYFUNCTION("""COMPUTED_VALUE"""),"Breaker") -> Breaker | I1: =IFERROR(__xludf.DUMMYFUNCTION("""COMPUTED_VALUE"""),"sum Power draw") -> sum Power draw | J1: Attached Electrical Items
A2: =IFERROR(__xludf.DUMMYFUNCTION("""COMPUTED_VALUE"""),"Main") -> Main | B2: =IFERROR(__xludf.DUMMYFUNCTION("""COMPUTED_VALUE"""),"M10L") -> M10L | C2: =IFERROR(__xludf.DUMMYFUNCTION("""COMPUTED_VALUE"""),2100.0) -> 2100 | D2: =IFERROR(__xludf.DUMMYFUNCTION("join("", "",filter('Electrical Items'!$F$2:$F$179,'Electrical Items'!$H$2:$H$179=B2))"),"F-Ki-O03, F-Ki-O02, F-Ki-O01, F-D-O03") -> F-Ki-O03, F-Ki-O02, F-Ki-O01, F-D-O03 | G2: =IFERROR(__xludf.DUMMYFUNCTION("""COMPUTED_VALUE"""),"Utility Subpanel") -> Utility Subpanel | H2: =IFERROR(__xludf.DUMMYFUNCTION("""COMPUTED_VALUE"""),"U10B") -> U10B | I2: =IFERROR(__xludf.DUMMYFUNCTION("""COMPUTED_VALUE"""),0.0) -> 0 | J2: =IFERROR(__xludf.DUMMYFUNCTION("join("", "",filter('Electrical Items'!$F$2:$F$179,'Electrical Items'!$H$2:$H$179=H2))"),"B-UR-O02, B-UR-O01, B-Ab-O09") -> B-UR-O02, B-UR-O01, B-Ab-O09
A3: =IFERROR(__xludf.DUMMYFUNCTION("""COMPUTED_VALUE"""),"Main") -> Main | B3: =IFERROR(__xludf.DUMMYFUNCTION("""COMPUTED_VALUE"""),"M11L") -> M11L | C3: =IFERROR(__xludf.DUMMYFUNCTION("""COMPUTED_VALUE"""),0.0) -> 0 | D3: =IFERROR(__xludf.DUMMYFUNCTION("join("", "",filter('Electrical Items'!$F$2:$F$179,'Electrical Items'!$H$2:$H$179=B3))"),"F-H-O04, F-H-O03, F-H-O02") -> F-H-O04, F-H-O03, F-H-O02 | G3: =IFERROR(__xludf.DUMMYFUNCTION("""COMPUTED_VALUE"""),"Utility Subpanel") -> Utility Subpanel | H3: =IFERROR(__xludf.DUMMYFUNCTION("""COMPUTED_VALUE"""),"U10T") -> U10T | I3: =IFERROR(__xludf.DUMMYFUNCTION("""COMPUTED_VALUE"""),2307.0) -> 2307 | J3: =IFERROR(__xludf.DUMMYFUNCTION("join("", "",filter('Electrical Items'!$F$2:$F$179,'Electrical Items'!$H$2:$H$179=H3))"),"B-UC-O02, B-UC-O01, B-UC-L01, B-S-O10, B-S-O09, B-Ab-O08, B-Ab-O07, B-Ab-O06, B-Ab-O05, B-Ab-O04, B-Ab-O03, B-Ab-O02, B-Ab-L01") -> B-UC-O02, B-UC-O01, B-UC-L01, B-S-O10, B-S-O09, B-Ab-O08, B-Ab-O07, B-Ab-O06, B-Ab-O05, B-Ab-O04, B-Ab-O03, B-Ab-O02, B-Ab-L01
A4: =IFERROR(__xludf.DUMMYFUNCTION("""COMPUTED_VALUE"""),"Main") -> Main | B4: =IFERROR(__xludf.DUMMYFUNCTION("""COMPUTED_VALUE"""),"M11R") -> M11R | C4: =IFERROR(__xludf.DUMMYFUNCTION("""COMPUTED_VALUE"""),390.0) -> 390 | D4: =IFERROR(__xludf.DUMMYFUNCTION("join("", "",filter('Electrical Items'!$F$2:$F$179,'Electrical Items'!$H$2:$H$179=B4))"),"T-BR-O07, T-BR-O06, T-BR-O05, T-BR-O04, T-BR-O03, T-BR-O02, T-BR-L01, T-BR-O01") -> T-BR-O07, T-BR-O06, T-BR-O05, T-BR-O04, T-BR-O03, T-BR-O02, T-BR-L01, T-BR-O01 | G4: =IFERROR(__xludf.DUMMYFUNCTION("""COMPUTED_VALUE"""),"Utility Subpanel") -> Utility Subpanel | H4: =IFERROR(__xludf.DUMMYFUNCTION("""COMPUTED_VALUE"""),"U12B") -> U12B | I4: =IFERROR(__xludf.DUMMYFUNCTION("""COMPUTED_VALUE"""),3110.0) -> 3110 | J4: =IFERROR(__xludf.DUMMYFUNCTION("join("", "",filter('Electrical Items'!$F$2:$F$179,'Electrical Items'!$H$2:$H$179=H4))"),"T-MB-O03, T-MB-O02, T-MB-O01, B-S-O02, B-S-O01, B-S-L01, B-Ab-O01, B-Ab-B-O01, B-Ab-B-LF01, B-Ab-B-L01") -> T-MB-O03, T-MB-O02, T-MB-O01, B-S-O02, B-S-O01, B-S-L01, B-Ab-O01, B-Ab-B-O01, B-Ab-B-LF01, B-Ab-B-L01
A5: =IFERROR(__xludf.DUMMYFUNCTION("""COMPUTED_VALUE"""),"Main") -> Main | B5: =IFERROR(__xludf.DUMMYFUNCTION("""COMPUTED_VALUE"""),"M12L") -> M12L | D5: =IFERROR(__xludf.DUMMYFUNCTION("join("", "",filter('Electrical Items'!$F$2:$F$179,'Electrical Items'!$H$2:$H$179=B5))"),"T-La-O02") -> T-La-O02 | G5: =IFERROR(__xludf.DUMMYFUNCTION("""COMPUTED_VALUE"""),"Utility Subpanel") -> Utility Subpanel | H5: =IFERROR(__xludf.DUMMYFUNCTION("""COMPUTED_VALUE"""),"U12T") -> U12T | I5: =IFERROR(__xludf.DUMMYFUNCTION("""COMPUTED_VALUE"""),150.0) -> 150 | J5: =IFERROR(__xludf.DUMMYFUNCTION("join("", "",filter('Electrical Items'!$F$2:$F$179,'Electrical Items'!$H$2:$H$179=H5))"),"F-Ki-O06, F-Ki-O05, F-Ki-O04, F-Ki-L08, B-Ab-L02") -> F-Ki-O06, F-Ki-O05, F-Ki-O04, F-Ki-L08, B-Ab-L02
A6: =IFERROR(__xludf.DUMMYFUNCTION("""COMPUTED_VALUE"""),"Main") -> Main | B6: =IFERROR(__xludf.DUMMYFUNCTION("""COMPUTED_VALUE"""),"M13L") -> M13L | C6: =IFERROR(__xludf.DUMMYFUNCTION("""COMPUTED_VALUE"""),1620.0) -> 1620 | D6: =IFERROR(__xludf.DUMMYFUNCTION("join("", "",filter('Electrical Items'!$F$2:$F$179,'Electrical Items'!$H$2:$H$179=B6))"),"F-Ki-O11, F-Ki-O10, F-Ki-O09") -> F-Ki-O11, F-Ki-O10, F-Ki-O09 | G6: =IFERROR(__xludf.DUMMYFUNCTION("""COMPUTED_VALUE"""),"Utility Subpanel") -> Utility Subpanel | H6: =IFERROR(__xludf.DUMMYFUNCTION("""COMPUTED_VALUE"""),"U2+4") -> U2+4 | I6: =IFERROR(__xludf.DUMMYFUNCTION("""COMPUTED_VALUE"""),4800.0) -> 4800 | J6: =IFERROR(__xludf.DUMMYFUNCTION("join("", "",filter('Electrical Items'!$F$2:$F$179,'Electrical Items'!$H$2:$H$179=H6))"),"B-Ab-ST") -> B-Ab-ST
A7: =IFERROR(__xludf.DUMMYFUNCTION("""COMPUTED_VALUE"""),"Main") -> Main | B7: =IFERROR(__xludf.DUMMYFUNCTION("""COMPUTED_VALUE"""),"M13R") -> M13R | C7: =IFERROR(__xludf.DUMMYFUNCTION("""COMPUTED_VALUE"""),0.0) -> 0 | D7: =IFERROR(__xludf.DUMMYFUNCTION("join("", "",filter('Electrical Items'!$F$2:$F$179,'Electrical Items'!$H$2:$H$179=B7))"),"F-PR-O03, F-PR-O02, F-PR-O01") -> F-PR-O03, F-PR-O02, F-PR-O01 | G7: =IFERROR(__xludf.DUMMYFUNCTION("""COMPUTED_VALUE"""),"Utility Subpanel") -> Utility Subpanel | H7: =IFERROR(__xludf.DUMMYFUNCTION("""COMPUTED_VALUE"""),"U6B") -> U6B | I7: =IFERROR(__xludf.DUMMYFUNCTION("""COMPUTED_VALUE"""),0.0) -> 0 | J7: =IFERROR(__xludf.DUMMYFUNCTION("join("", "",filter('Electrical Items'!$F$2:$F$179,'Electrical Items'!$H$2:$H$179=H7))"),"B-UR-O01, B-A-O02") -> B-UR-O01, B-A-O02
A8: =IFERROR(__xludf.DUMMYFUNCTION("""COMPUTED_VALUE"""),"Main") -> Main | B8: =IFERROR(__xludf.DUMMYFUNCTION("""COMPUTED_VALUE"""),"M14L") -> M14L | C8: =IFERROR(__xludf.DUMMYFUNCTION("""COMPUTED_VALUE"""),180.0) -> 180 | D8: =IFERROR(__xludf.DUMMYFUNCTION("join("", "",filter('Electrical Items'!$F$2:$F$179,'Electrical Items'!$H$2:$H$179=B8))"),"T-Ha-O01, T-Ha-L01, T-Mx-O05, T-Mx-O04, T-Mx-O03, T-Mx-O02, T-Mx-O01, T-Mx-L01, T-Th-L01") -> T-Ha-O01, T-Ha-L01, T-Mx-O05, T-Mx-O04, T-Mx-O03, T-Mx-O02, T-Mx-O01, T-Mx-L01, T-Th-L01 | G8: =IFERROR(__xludf.DUMMYFUNCTION("""COMPUTED_VALUE"""),"Utility Subpanel") -> Utility Subpanel | H8: =IFERROR(__xludf.DUMMYFUNCTION("""COMPUTED_VALUE"""),"U6T") -> U6T | I8: =IFERROR(__xludf.DUMMYFUNCTION("""COMPUTED_VALUE"""),1500.0) -> 1500 | J8: =IFERROR(__xludf.DUMMYFUNCTION("join("", "",filter('Electrical Items'!$F$2:$F$179,'Electrical Items'!$H$2:$H$179=H8))"),"B-Ab-O10, B-Ab-MW") -> B-Ab-O10, B-Ab-MW
A9: =IFERROR(__xludf.DUMMYFUNCTION("""COMPUTED_VALUE"""),"Main") -> Main | B9: =IFERROR(__xludf.DUMMYFUNCTION("""COMPUTED_VALUE"""),"M14R") -> M14R | C9: =IFERROR(__xludf.DUMMYFUNCTION("""COMPUTED_VALUE"""),610.0) -> 610 | D9: =IFERROR(__xludf.DUMMYFUNCTION("join("", "",filter('Electrical Items'!$F$2:$F$179,'Electrical Items'!$H$2:$H$179=B9))"),"T-BR-CF01, T-BR-LS01, T-BR-LS02, T-BR-L01, T-La-L01, T-Th-O05, T-Th-O04, T-Th-O03, T-Th-O02, T-Th-O01, F-Ki-LS03, F-Ki-L03") -> T-BR-CF01, T-BR-LS01, T-BR-LS02, T-BR-L01, T-La-L01, T-Th-O05, T-Th-O04, T-Th-O03, T-Th-O02, T-Th-O01, F-Ki-LS03, F-Ki-L03 | G9: =IFERROR(__xludf.DUMMYFUNCTION("""COMPUTED_VALUE"""),"Utility Subpanel") -> Utility Subpanel | H9: =IFERROR(__xludf.DUMMYFUNCTION("""COMPUTED_VALUE"""),"U8B") -> U8B | I9: =IFERROR(__xludf.DUMMYFUNCTION("""COMPUTED_VALUE"""),30.0) -> 30 | J9: =IFERROR(__xludf.DUMMYFUNCTION("join("", "",filter('Electrical Items'!$F$2:$F$179,'Electrical Items'!$H$2:$H$179=H9))"),"B-Pa-L02, B-Ab-O12") -> B-Pa-L02, B-Ab-O12
A10: =IFERROR(__xludf.DUMMYFUNCTION("""COMPUTED_VALUE"""),"Main") -> Main | B10: =IFERROR(__xludf.DUMMYFUNCTION("""COMPUTED_VALUE"""),"M15L") -> M15L | C10: =IFERROR(__xludf.DUMMYFUNCTION("""COMPUTED_VALUE"""),1330.0) -> 1330 | D10: =IFERROR(__xludf.DUMMYFUNCTION("join("", "",filter('Electrical Items'!$F$2:$F$179,'Electrical Items'!$H$2:$H$179=B10))"),"F-Ki-DW, B-UR-L01, B-Ab-F01") -> F-Ki-DW, B-UR-L01, B-Ab-F01 | G10: =IFERROR(__xludf.DUMMYFUNCTION("""COMPUTED_VALUE"""),"Utility Subpanel") -> Utility Subpanel | H10: =IFERROR(__xludf.DUMMYFUNCTION("""COMPUTED_VALUE"""),"U8T") -> U8T | I10: =IFERROR(__xludf.DUMMYFUNCTION("""COMPUTED_VALUE"""),0.0) -> 0 | J10: =IFERROR(__xludf.DUMMYFUNCTION("join("", "",filter('Electrical Items'!$F$2:$F$179,'Electrical Items'!$H$2:$H$179=H10))"),"B-Ab-O11") -> B-Ab-O11
A11: =IFERROR(__xludf.DUMMYFUNCTION("""COMPUTED_VALUE"""),"Main") -> Main | B11: =IFERROR(__xludf.DUMMYFUNCTION("""COMPUTED_VALUE"""),"M17") -> M17 | C11: =IFERROR(__xludf.DUMMYFUNCTION("""COMPUTED_VALUE"""),2938.0) -> 2938 | D11: =IFERROR(__xludf.DUMMYFUNCTION("join("", "",filter('Electrical Items'!$F$2:$F$179,'Electrical Items'!$H$2:$H$179=B11))"),"F-Po-O01, F-Po-L01, F-LR-O06, F-LR-O05, F-LR-O04, F-LR-O03, F-LR-O02, F-LR-L03, F-LR-L02, F-LR-L01, F-Ki-O08, F-Ki-L07, F-Ki-L05, F-Ki-L02, F-H-O01, F-H-L05, F-H-L04, F-GB-O02, F-GB-O01, F-GB-L01, F-D-O02, F-D-O01, F-D-L03, F-D-L02, F-D-L01, B-UR-L01, B-U"&"C-O01, B-S-O08, B-S-O07, B-S-O06, B-S-O05, B-S-O03, B-Pa-O02, B-Pa-O02, B-Pa-O01, B-Pa-L03, B-Pa-L01, B-A-O01") -> F-Po-O01, F-Po-L01, F-LR-O06, F-LR-O05, F-LR-O04, F-LR-O03, F-LR-O02, F-LR-L03, F-LR-L02, F-LR-L01, F-Ki-O08, F-Ki-L07, F-Ki-L05, F-Ki-L02, F-H-O01, F-H-L05, F-H-L04, F-GB-O02, F-GB-O01, F-GB-L01, F-D-O02, F-D-O01, F-D-L03, F-D-L02, F-D-L01, B-UR-L01, B-UC-O01, B-S-O08, B-S-O07, B-S-O06, B-S-O05, B-S-O03, B-Pa-O02, B-Pa-O02, B-Pa-O01, B-Pa-L03, B-Pa-L01, B-A-O01 | J11: =IFERROR(__xludf.DUMMYFUNCTION("join("", "",filter('Electrical Items'!$F$2:$F$179,'Electrical Items'!$H$2:$H$179=H11))"),"T-BR-HP04, B-UR-HP02, B-UC-HP01") -> T-BR-HP04, B-UR-HP02, B-UC-HP01
A12: =IFERROR(__xludf.DUMMYFUNCTION("""COMPUTED_VALUE"""),"Main") -> Main | B12: =IFERROR(__xludf.DUMMYFUNCTION("""COMPUTED_VALUE"""),"M19L") -> M19L | C12: =IFERROR(__xludf.DUMMYFUNCTION("""COMPUTED_VALUE"""),0.0) -> 0 | D12: =IFERROR(__xludf.DUMMYFUNCTION("join("", "",filter('Electrical Items'!$F$2:$F$179,'Electrical Items'!$H$2:$H$179=B12))"),"F-Ki-MW") -> F-Ki-MW
A13: =IFERROR(__xludf.DUMMYFUNCTION("""COMPUTED_VALUE"""),"Main") -> Main | B13: =IFERROR(__xludf.DUMMYFUNCTION("""COMPUTED_VALUE"""),"M19R") -> M19R | C13: =IFERROR(__xludf.DUMMYFUNCTION("""COMPUTED_VALUE"""),2221.0) -> 2221 | D13: =IFERROR(__xludf.DUMMYFUNCTION("join("", "",filter('Electrical Items'!$F$2:$F$179,'Electrical Items'!$H$2:$H$179=B13))"),"T-Ba-O01, T-Ba-L01, T-GB-O02, T-GB-O01, T-GB-L10, T-Ha-L02, T-Ma-O07, T-Ma-O06, T-Ma-O05, T-Ma-O04, T-Ma-O03, T-Ma-O02, T-Ma-O01, T-Ma-L03, T-Ma-L02, T-Ma-L01, T-Ma-F01, T-MB-LF01, T-MB-L02, T-MB-L02, T-MB-L01, T-Wi-O06, T-Wi-O05, T-Wi-O04, T-Wi-O03, T-Wi"&"-O02, T-Wi-O01, T-Wi-L02, T-Wi-L01") -> T-Ba-O01, T-Ba-L01, T-GB-O02, T-GB-O01, T-GB-L10, T-Ha-L02, T-Ma-O07, T-Ma-O06, T-Ma-O05, T-Ma-O04, T-Ma-O03, T-Ma-O02, T-Ma-O01, T-Ma-L03, T-Ma-L02, T-Ma-L01, T-Ma-F01, T-MB-LF01, T-MB-L02, T-MB-L02, T-MB-L01, T-Wi-O06, T-Wi-O05, T-Wi-O04, T-Wi-O03, T-Wi-O02, T-Wi-O01, T-Wi-L02, T-Wi-L01
A14: =IFERROR(__xludf.DUMMYFUNCTION("""COMPUTED_VALUE"""),"Main") -> Main | B14: =IFERROR(__xludf.DUMMYFUNCTION("""COMPUTED_VALUE"""),"M2+4") -> M2+4 | C14: =IFERROR(__xludf.DUMMYFUNCTION("""COMPUTED_VALUE"""),9800.0) -> 9800 | D14: =IFERROR(__xludf.DUMMYFUNCTION("join("", "",filter('Electrical Items'!$F$2:$F$179,'Electrical Items'!$H$2:$H$179=B14))"),"F-Ki-ST, F-Ki-OV") -> F-Ki-ST, F-Ki-OV
A15: =IFERROR(__xludf.DUMMYFUNCTION("""COMPUTED_VALUE"""),"Main") -> Main | B15: =IFERROR(__xludf.DUMMYFUNCTION("""COMPUTED_VALUE"""),"M20") -> M20 | C15: =IFERROR(__xludf.DUMMYFUNCTION("""COMPUTED_VALUE"""),990.0) -> 990 | D15: =IFERROR(__xludf.DUMMYFUNCTION("join("", "",filter('Electrical Items'!$F$2:$F$179,'Electrical Items'!$H$2:$H$179=B15))"),"F-PR-L02, F-PR-L01, F-LR-O09, F-LR-O08, F-LR-O07, F-LR-O01, F-Ki-L01, F-Ga-O02, F-Ga-O01, F-Ga-L01, F-Ga-O02, F-Ga-O03, F-Ga-O04") -> F-PR-L02, F-PR-L01, F-LR-O09, F-LR-O08, F-LR-O07, F-LR-O01, F-Ki-L01, F-Ga-O02, F-Ga-O01, F-Ga-L01, F-Ga-O02, F-Ga-O03, F-Ga-O04
A16: =IFERROR(__xludf.DUMMYFUNCTION("""COMPUTED_VALUE"""),"Main") -> Main | B16: =IFERROR(__xludf.DUMMYFUNCTION("""COMPUTED_VALUE"""),"M5+7") -> M5+7 | D16: =IFERROR(__xludf.DUMMYFUNCTION("join("", "",filter('Electrical Items'!$F$2:$F$179,'Electrical Items'!$H$2:$H$179=B16))"),"T-La-O01") -> T-La-O01
A17: =IFERROR(__xludf.DUMMYFUNCTION("""COMPUTED_VALUE"""),"Main") -> Main | B17: =IFERROR(__xludf.DUMMYFUNCTION("""COMPUTED_VALUE"""),"M9L") -> M9L | C17: =IFERROR(__xludf.DUMMYFUNCTION("""COMPUTED_VALUE"""),1050.0) -> 1050 | D17: =IFERROR(__xludf.DUMMYFUNCTION("join("", "",filter('Electrical Items'!$F$2:$F$179,'Electrical Items'!$H$2:$H$179=B17))"),"F-Ki-O07, F-Ki-L06, F-Ki-L04") -> F-Ki-O07, F-Ki-L06, F-Ki-L04
A20: TOTALS | B20: =countA(B2:B17) -> 16 | C20: =sum(C2:C17) -> 23229 | G20: TOTALS | H20: =countA(H2:H17) -> 9 | I20: =sum(I2:I17) -> 11897

Sheet Electrical Items
A1: Floor | B1: Floor name | C1: Room | D1: Room name | E1: Item | F1: ItemFull | G1: Item name | H1: Breaker | I1: Breaker Box | J1: Verified | K1: Power draw | L1: Attached Device 1 | M1: Power 1 | N1: Attached Device 2 | O1: Power 2 | P1: Attached Device 3 | Q1: Power 3 | R1: Attached Device 4 | S1: Power 4 | T1: Attached Device 5 | U1: Power 5 | V1: Attached Device 6 | W1: Power 6 | X1: Attached Device 7 | Y1: Power 7
A2: T | B2: {=IF(ISBLANK(A2),"",XLOOKUP(A2, FloorsTbl[Floor], FloorsTbl[Floor name]))} -> Top floor | C2: Ba | D2: {=IF(ISBLANK(C2),"",XLOOKUP(C2, RoomsTbl[Room], RoomsTbl[Room Name]))} -> Balcony | E2: O01 | F2: =IF(ISBLANK(E2),"",A2&"-"&C2&"-"&E2) -> T-Ba-O01 | G2: Outlet left | H2: M19R | I2: =IF(ISBLANK(H2),"",VLOOKUP(H2,Breakers!$B$2:$C$44,2)) -> Main | J2: =CHAR(10004) -> ✔ | K2: =+M2+O2+Q2+S2+U2+W2+Y2 -> 0 | M2: {=IF(ISBLANK(L2),"",XLOOKUP(L2, DeviceWattagesTbl[Device], DeviceWattagesTbl[Power]))} | O2: {=IF(ISBLANK(N2),"",XLOOKUP(N2, DeviceWattagesTbl[Device], DeviceWattagesTbl[Power]))} | Q2: {=IF(ISBLANK(P2),"",XLOOKUP(P2, DeviceWattagesTbl[Device], DeviceWattagesTbl[Power]))} | S2: {=IF(ISBLANK(R2),"",XLOOKUP(R2, DeviceWattagesTbl[Device], DeviceWattagesTbl[Power]))} | U2: {=IF(ISBLANK(T2),"",XLOOKUP(T2, DeviceWattagesTbl[Device], DeviceWattagesTbl[Power]))} | W2: {=IF(ISBLANK(V2),"",XLOOKUP(V2, DeviceWattagesTbl[Device], DeviceWattagesTbl[Power]))} | Y2: {=IF(ISBLANK(X2),"",XLOOKUP(X2, DeviceWattagesTbl[Device], DeviceWattagesTbl[Power]))}
A3: T | B3: {=IF(ISBLANK(A3),"",XLOOKUP(A3, FloorsTbl[Floor], FloorsTbl[Floor name]))} -> Top floor | C3: Ba | D3: {=IF(ISBLANK(C3),"",XLOOKUP(C3, RoomsTbl[Room], RoomsTbl[Room Name]))} -> Balcony | E3: L01 | F3: =IF(ISBLANK(E3),"",A3&"-"&C3&"-"&E3) -> T-Ba-L01 | G3: Light left | H3: M19R | I3: =IF(ISBLANK(H3),"",VLOOKUP(H3,Breakers!$B$2:$C$44,2)) -> Main | J3: =CHAR(10004) -> ✔ | K3: =+M3+O3+Q3+S3+U3+W3+Y3 -> 30 | L3: LED Lamp | M3: {=IF(ISBLANK(L3),"",XLOOKUP(L3, DeviceWattagesTbl[Device], DeviceWattagesTbl[Power]))} -> 30 | O3: {=IF(ISBLANK(N3),"",XLOOKUP(N3, DeviceWattagesTbl[Device], DeviceWattagesTbl[Power]))} | Q3: {=IF(ISBLANK(P3),"",XLOOKUP(P3, DeviceWattagesTbl[Device], DeviceWattagesTbl[Power]))} | S3: {=IF(ISBLANK(R3),"",XLOOKUP(R3, DeviceWattagesTbl[Device], DeviceWattagesTbl[Power]))} | U3: {=IF(ISBLANK(T3),"",XLOOKUP(T3, DeviceWattagesTbl[Device], DeviceWattagesTbl[Power]))} | W3: {=IF(ISBLANK(V3),"",XLOOKUP(V3, DeviceWattagesTbl[Device], DeviceWattagesTbl[Power]))} | Y3: {=IF(ISBLANK(X3),"",XLOOKUP(X3, DeviceWattagesTbl[Device], DeviceWattagesTbl[Power]))}
A4: T | B4: {=IF(ISBLANK(A4),"",XLOOKUP(A4, FloorsTbl[Floor], FloorsTbl[Floor name]))} -> Top floor | C4: BR | D4: {=IF(ISBLANK(C4),"",XLOOKUP(C4, RoomsTbl[Room], RoomsTbl[Room Name]))} -> Bonus Room | E4: F01 | F4: =IF(ISBLANK(E4),"",A4&"-"&C4&"-"&E4) -> T-BR-F01 | G4: Fan ceiling | H4: ? | I4: =IF(ISBLANK(H4),"",VLOOKUP(H4,Breakers!$B$2:$C$44,2)) -> ? | K4: =+M4+O4+Q4+S4+U4+W4+Y4 -> #N/A | L4: It's on Light circuit in room and currently connected to switch, which needs to be undone | M4: {=IF(ISBLANK(L4),"",XLOOKUP(L4, DeviceWattagesTbl[Device], DeviceWattagesTbl[Power]))} -> #N/A | O4: {=IF(ISBLANK(N4),"",XLOOKUP(N4, DeviceWattagesTbl[Device], DeviceWattagesTbl[Power]))} | Q4: {=IF(ISBLANK(P4),"",XLOOKUP(P4, DeviceWattagesTbl[Device], DeviceWattagesTbl[Power]))} | S4: {=IF(ISBLANK(R4),"",XLOOKUP(R4, DeviceWattagesTbl[Device], DeviceWattagesTbl[Power]))} | U4: {=IF(ISBLANK(T4),"",XLOOKUP(T4, DeviceWattagesTbl[Device], DeviceWattagesTbl[Power]))} | W4: {=IF(ISBLANK(V4),"",XLOOKUP(V4, DeviceWattagesTbl[Device], DeviceWattagesTbl[Power]))} | Y4: {=IF(ISBLANK(X4),"",XLOOKUP(X4, DeviceWattagesTbl[Device], DeviceWattagesTbl[Power]))}
A5: T | B5: {=IF(ISBLANK(A5),"",XLOOKUP(A5, FloorsTbl[Floor], FloorsTbl[Floor name]))} -> Top floor | C5: BR | D5: {=IF(ISBLANK(C5),"",XLOOKUP(C5, RoomsTbl[Room], RoomsTbl[Room Name]))} -> Bonus Room | E5: O07 | F5: =IF(ISBLANK(E5),"",A5&"-"&C5&"-"&E5) -> T-BR-O07 | G5: Outlet right back | H5: M11R | I5: =IF(ISBLANK(H5),"",VLOOKUP(H5,breaker_info,2)) -> Main | J5: =CHAR(10004) -> ✔ | K5: =+M5+O5+Q5+S5+U5+W5+Y5 -> 30 | L5: LED Lamp | M5: {=IF(ISBLANK(L5),"",XLOOKUP(L5, DeviceWattagesTbl[Device], DeviceWattagesTbl[Power]))} -> 30 | O5: {=IF(ISBLANK(N5),"",XLOOKUP(N5, DeviceWattagesTbl[Device], DeviceWattagesTbl[Power]))} | Q5: {=IF(ISBLANK(P5),"",XLOOKUP(P5, DeviceWattagesTbl[Device], DeviceWattagesTbl[Power]))} | S5: {=IF(ISBLANK(R5),"",XLOOKUP(R5, DeviceWattagesTbl[Device], DeviceWattagesTbl[Power]))} | U5: {=IF(ISBLANK(T5),"",XLOOKUP(T5, DeviceWattagesTbl[Device], DeviceWattagesTbl[Power]))} | W5: {=IF(ISBLANK(V5),"",XLOOKUP(V5, DeviceWattagesTbl[Device], DeviceWattagesTbl[Power]))} | Y5: {=IF(ISBLANK(X5),"",XLOOKUP(X5, DeviceWattagesTbl[Device], DeviceWattagesTbl[Power]))}
A6: T | B6: {=IF(ISBLANK(A6),"",XLOOKUP(A6, FloorsTbl[Floor], FloorsTbl[Floor name]))} -> Top floor | C6: BR | D6: {=IF(ISBLANK(C6),"",XLOOKUP(C6, RoomsTbl[Room], RoomsTbl[Room Name]))} -> Bonus Room | E6: O06 | F6: =IF(ISBLANK(E6),"",A6&"-"&C6&"-"&E6) -> T-BR-O06 | G6: Outlet back right | H6: M11R | I6: =IF(ISBLANK(H6),"",VLOOKUP(H6,Breakers!$B$2:$C$44,2)) -> Main | J6: =CHAR(10004) -> ✔ | K6: =+M6+O6+Q6+S6+U6+W6+Y6 -> 30 | L6: LED Lamp | M6: {=IF(ISBLANK(L6),"",XLOOKUP(L6, DeviceWattagesTbl[Device], DeviceWattagesTbl[Power]))} -> 30 | O6: {=IF(ISBLANK(N6),"",XLOOKUP(N6, DeviceWattagesTbl[Device], DeviceWattagesTbl[Power]))} | Q6: {=IF(ISBLANK(P6),"",XLOOKUP(P6, DeviceWattagesTbl[Device], DeviceWattagesTbl[Power]))} | S6: {=IF(ISBLANK(R6),"",XLOOKUP(R6, DeviceWattagesTbl[Device], DeviceWattagesTbl[Power]))} | U6: {=IF(ISBLANK(T6),"",XLOOKUP(T6, DeviceWattagesTbl[Device], DeviceWattagesTbl[Power]))} | W6: {=IF(ISBLANK(V6),"",XLOOKUP(V6, DeviceWattagesTbl[Device], DeviceWattagesTbl[Power]))} | Y6: {=IF(ISBLANK(X6),"",XLOOKUP(X6, DeviceWattagesTbl[Device], DeviceWattagesTbl[Power]))}
A7: T | B7: {=IF(ISBLANK(A7),"",XLOOKUP(A7, FloorsTbl[Floor], FloorsTbl[Floor name]))} -> Top floor | C7: BR | D7: {=IF(ISBLANK(C7),"",XLOOKUP(C7, RoomsTbl[Room], RoomsTbl[Room Name]))} -> Bonus Room | E7: O05 | F7: =IF(ISBLANK(E7),"",A7&"-"&C7&"-"&E7) -> T-BR-O05 | G7: Outlet back left | H7: M11R | I7: =IF(ISBLANK(H7),"",VLOOKUP(H7,Breakers!$B$2:$C$44,2)) -> Main | J7: =CHAR(10004) -> ✔ | K7: =+M7+O7+Q7+S7+U7+W7+Y7 -> 30 | L7: LED Lamp | M7: {=IF(ISBLANK(L7),"",XLOOKUP(L7, DeviceWattagesTbl[Device], DeviceWattagesTbl[Power]))} -> 30 | O7: {=IF(ISBLANK(N7),"",XLOOKUP(N7, DeviceWattagesTbl[Device], DeviceWattagesTbl[Power]))} | Q7: {=IF(ISBLANK(P7),"",XLOOKUP(P7, DeviceWattagesTbl[Device], DeviceWattagesTbl[Power]))} | S7: {=IF(ISBLANK(R7),"",XLOOKUP(R7, DeviceWattagesTbl[Device], DeviceWattagesTbl[Power]))} | U7: {=IF(ISBLANK(T7),"",XLOOKUP(T7, DeviceWattagesTbl[Device], DeviceWattagesTbl[Power]))} | W7: {=IF(ISBLANK(V7),"",XLOOKUP(V7, DeviceWattagesTbl[Device], DeviceWattagesTbl[Power]))} | Y7: {=IF(ISBLANK(X7),"",XLOOKUP(X7, DeviceWattagesTbl[Device], DeviceWattagesTbl[Power]))}
A8: T | B8: {=IF(ISBLANK(A8),"",XLOOKUP(A8, FloorsTbl[Floor], FloorsTbl[Floor name]))} -> Top floor | C8: BR | D8: {=IF(ISBLANK(C8),"",XLOOKUP(C8, RoomsTbl[Room], RoomsTbl[Room Name]))} -> Bonus Room | E8: O04 | F8: =IF(ISBLANK(E8),"",A8&"-"&C8&"-"&E8) -> T-BR-O04 | G8: Outlet left back | H8: M11R | I8: =IF(ISBLANK(H8),"",VLOOKUP(H8,Breakers!$B$2:$C$44,2)) -> Main | J8: =CHAR(10004) -> ✔ | K8: =+M8+O8+Q8+S8+U8+W8+Y8 -> 30 | L8: LED Lamp | M8: {=IF(ISBLANK(L8),"",XLOOKUP(L8, DeviceWattagesTbl[Device], DeviceWattagesTbl[Power]))} -> 30 | O8: {=IF(ISBLANK(N8),"",XLOOKUP(N8, DeviceWattagesTbl[Device], DeviceWattagesTbl[Power]))} | Q8: {=IF(ISBLANK(P8),"",XLOOKUP(P8, DeviceWattagesTbl[Device], DeviceWattagesTbl[Power]))} | S8: {=IF(ISBLANK(R8),"",XLOOKUP(R8, DeviceWattagesTbl[Device], DeviceWattagesTbl[Power]))} | U8: {=IF(ISBLANK(T8),"",XLOOKUP(T8, DeviceWattagesTbl[Device], DeviceWattagesTbl[Power]))} | W8: {=IF(ISBLANK(V8),"",XLOOKUP(V8, DeviceWattagesTbl[Device], DeviceWattagesTbl[Power]))} | Y8: {=IF(ISBLANK(X8),"",XLOOKUP(X8, DeviceWattagesTbl[Device], DeviceWattagesTbl[Power]))}
A9: T | B9: {=IF(ISBLANK(A9),"",XLOOKUP(A9, FloorsTbl[Floor], FloorsTbl[Floor name]))} -> Top floor | C9: BR | D9: {=IF(ISBLANK(C9),"",XLOOKUP(C9, RoomsTbl[Room], RoomsTbl[Room Name]))} -> Bonus Room | E9: O03 | F9: =IF(ISBLANK(E9),"",A9&"-"&C9&"-"&E9) -> T-BR-O03 | G9: Outlet left front | H9: M11R | I9: =IF(ISBLANK(H9),"",VLOOKUP(H9,Breakers!$B$2:$C$44,2)) -> Main | J9: =CHAR(10004) -> ✔ | K9: =+M9+O9+Q9+S9+U9+W9+Y9 -> 30 | L9: LED Lamp | M9: {=IF(ISBLANK(L9),"",XLOOKUP(L9, DeviceWattagesTbl[Device], DeviceWattagesTbl[Power]))} -> 30 | O9: {=IF(ISBLANK(N9),"",XLOOKUP(N9, DeviceWattagesTbl[Device], DeviceWattagesTbl[Power]))} | Q9: {=IF(ISBLANK(P9),"",XLOOKUP(P9, DeviceWattagesTbl[Device], DeviceWattagesTbl[Power]))} | S9: {=IF(ISBLANK(R9),"",XLOOKUP(R9, DeviceWattagesTbl[Device], DeviceWattagesTbl[Power]))} | U9: {=IF(ISBLANK(T9),"",XLOOKUP(T9, DeviceWattagesTbl[Device], DeviceWattagesTbl[Power]))} | W9: {=IF(ISBLANK(V9),"",XLOOKUP(V9, DeviceWattagesTbl[Device], DeviceWattagesTbl[Power]))} | Y9: {=IF(ISBLANK(X9),"",XLOOKUP(X9, DeviceWattagesTbl[Device], DeviceWattagesTbl[Power]))}
A10: T | B10: {=IF(ISBLANK(A10),"",XLOOKUP(A10, FloorsTbl[Floor], FloorsTbl[Floor name]))} -> Top floor | C10: BR | D10: {=IF(ISBLANK(C10),"",XLOOKUP(C10, RoomsTbl[Room], RoomsTbl[Room Name]))} -> Bonus Room | E10: O02 | F10: =IF(ISBLANK(E10),"",A10&"-"&C10&"-"&E10) -> T-BR-O02 | G10: Outlet bed center | H10: M11R | I10: =IF(ISBLANK(H10),"",VLOOKUP(H10,Breakers!$B$2:$C$44,2)) -> Main | J10: =CHAR(10004) -> ✔ | K10: =+M10+O10+Q10+S10+U10+W10+Y10 -> 30 | L10: LED Lamp | M10: {=IF(ISBLANK(L10),"",XLOOKUP(L10, DeviceWattagesTbl[Device], DeviceWattagesTbl[Power]))} -> 30 | O10: {=IF(ISBLANK(N10),"",XLOOKUP(N10, DeviceWattagesTbl[Device], DeviceWattagesTbl[Power]))} | Q10: {=IF(ISBLANK(P10),"",XLOOKUP(P10, DeviceWattagesTbl[Device], DeviceWattagesTbl[Power]))} | S10: {=IF(ISBLANK(R10),"",XLOOKUP(R10, DeviceWattagesTbl[Device], DeviceWattagesTbl[Power]))} | U10: {=IF(ISBLANK(T10),"",XLOOKUP(T10, DeviceWattagesTbl[Device], DeviceWattagesTbl[Power]))} | W10: {=IF(ISBLANK(V10),"",XLOOKUP(V10, DeviceWattagesTbl[Device], DeviceWattagesTbl[Power]))} | Y10: {=IF(ISBLANK(X10),"",XLOOKUP(X10, DeviceWattagesTbl[Device], DeviceWattagesTbl[Power]))}
A11: T | B11: {=IF(ISBLANK(A11),"",XLOOKUP(A11, FloorsTbl[Floor], FloorsTbl[Floor name]))} -> Top floor | C11: BR | D11: {=IF(ISBLANK(C11),"",XLOOKUP(C11, RoomsTbl[Room], RoomsTbl[Room Name]))} -> Bonus Room | E11: L01 | F11: =IF(ISBLANK(E11),"",A11&"-"&C11&"-"&E11) -> T-BR-L01 | G11: LED Ceiling Lights | H11: M11R | I11: =IF(ISBLANK(H11),"",VLOOKUP(H11,Breakers!$B$2:$C$44,2)) -> Main | J11: =CHAR(10004) -> ✔ | K11: =+M11+O11+Q11+S11+U11+W11+Y11 -> 180 | L11: LED Lamp | M11: {=6*IF(ISBLANK(L11),"",XLOOKUP(L11, DeviceWattagesTbl[Device], DeviceWattagesTbl[Power]))} -> 180 | O11: {=IF(ISBLANK(N11),"",XLOOKUP(N11, DeviceWattagesTbl[Device], DeviceWattagesTbl[Power]))} | Q11: {=IF(ISBLANK(P11),"",XLOOKUP(P11, DeviceWattagesTbl[Device], DeviceWattagesTbl[Power]))} | S11: {=IF(ISBLANK(R11),"",XLOOKUP(R11, DeviceWattagesTbl[Device], DeviceWattagesTbl[Power]))} | U11: {=IF(ISBLANK(T11),"",XLOOKUP(T11, DeviceWattagesTbl[Device], DeviceWattagesTbl[Power]))} | W11: {=IF(ISBLANK(V11),"",XLOOKUP(V11, DeviceWattagesTbl[Device], DeviceWattagesTbl[Power]))} | Y11: {=IF(ISBLANK(X11),"",XLOOKUP(X11, DeviceWattagesTbl[Device], DeviceWattagesTbl[Power]))}
A12: T | B12: {=IF(ISBLANK(A12),"",XLOOKUP(A12, FloorsTbl[Floor], FloorsTbl[Floor name]))} -> Top floor | C12: BR | D12: {=IF(ISBLANK(C12),"",XLOOKUP(C12, RoomsTbl[Room], RoomsTbl[Room Name]))} -> Bonus Room | E12: CF01 | F12: =IF(ISBLANK(E12),"",A12&"-"&C12&"-"&E12) -> T-BR-CF01 | G12: Ceiling Fan | H12: M14R | I12: =IF(ISBLANK(H12),"",VLOOKUP(H12,Breakers!$B$2:$C$44,2)) -> Main | J12: =CHAR(10004) -> ✔ | K12: =+M12+O12+Q12+S12+U12+W12+Y12 -> 80 | L12: Ceiling Fan | M12: {=IF(ISBLANK(L12),"",XLOOKUP(L12, DeviceWattagesTbl[Device], DeviceWattagesTbl[Power]))} -> 80 | O12: {=IF(ISBLANK(N12),"",XLOOKUP(N12, DeviceWattagesTbl[Device], DeviceWattagesTbl[Power]))} | Q12: {=IF(ISBLANK(P12),"",XLOOKUP(P12, DeviceWattagesTbl[Device], DeviceWattagesTbl[Power]))} | S12: {=IF(ISBLANK(R12),"",XLOOKUP(R12, DeviceWattagesTbl[Device], DeviceWattagesTbl[Power]))} | U12: {=IF(ISBLANK(T12),"",XLOOKUP(T12, DeviceWattagesTbl[Device], DeviceWattagesTbl[Power]))} | W12: {=IF(ISBLANK(V12),"",XLOOKUP(V12, DeviceWattagesTbl[Device], DeviceWattagesTbl[Power]))} | Y12: {=IF(ISBLANK(X12),"",XLOOKUP(X12, DeviceWattagesTbl[Device], DeviceWattagesTbl[Power]))}
A13: T | B13: {=IF(ISBLANK(A13),"",XLOOKUP(A13, FloorsTbl[Floor], FloorsTbl[Floor name]))} -> Top floor | C13: BR | D13: {=IF(ISBLANK(C13),"",XLOOKUP(C13, RoomsTbl[Room], RoomsTbl[Room Name]))} -> Bonus Room | E13: LS01 | F13: =IF(ISBLANK(E13),"",A13&"-"&C13&"-"&E13) -> T-BR-LS01 | G13: 3W Light Switch (F-Ki-LS03) - near stairwall door | H13: M14R | I13: =IF(ISBLANK(H13),"",VLOOKUP(H13,Breakers!$B$2:$C$44,2)) -> Main | J13: =CHAR(10004) -> ✔ | K13: =+M13+O13+Q13+S13+U13+W13+Y13 -> 0 | L13: Light Switch | M13: {=IF(ISBLANK(L13),"",XLOOKUP(L13, DeviceWattagesTbl[Device], DeviceWattagesTbl[Power]))} -> 0 | O13: {=IF(ISBLANK(N13),"",XLOOKUP(N13, DeviceWattagesTbl[Device], DeviceWattagesTbl[Power]))} | Q13: {=IF(ISBLANK(P13),"",XLOOKUP(P13, DeviceWattagesTbl[Device], DeviceWattagesTbl[Power]))} | S13: {=IF(ISBLANK(R13),"",XLOOKUP(R13, DeviceWattagesTbl[Device], DeviceWattagesTbl[Power]))} | U13: {=IF(ISBLANK(T13),"",XLOOKUP(T13, DeviceWattagesTbl[Device], DeviceWattagesTbl[Power]))} | W13: {=IF(ISBLANK(V13),"",XLOOKUP(V13, DeviceWattagesTbl[Device], DeviceWattagesTbl[Power]))} | Y13: {=IF(ISBLANK(X13),"",XLOOKUP(X13, DeviceWattagesTbl[Device], DeviceWattagesTbl[Power]))}
A14: T | B14: {=IF(ISBLANK(A14),"",XLOOKUP(A14, Floors!$A$2:$A$6, Floors!$B$2:$B$6))} -> Top floor | C14: BR | D14: {=IF(ISBLANK(C14),"",XLOOKUP(C14, Rooms!$A$2:$A$29, Rooms!$B$2:$B$29))} -> Bonus Room | E14: LS02 | F14: =IF(ISBLANK(E14),"",A14&"-"&C14&"-"&E14) -> T-BR-LS02 | G14: Light Switch for Ceiling Lights | H14: M14R | I14: =IF(ISBLANK(H14),"",VLOOKUP(H14,Breakers!$B$2:$C$44,2)) -> Main | J14: =CHAR(10004) -> ✔ | K14: =+M14+O14+Q14+S14+U14+W14+Y14 -> 0 | L14: Light Switch | M14: {=IF(ISBLANK(L14),"",XLOOKUP(L14, 'Device Wattages'!$A$2:$A$55, 'Device Wattages'!$E$2:$E$55))} -> 0 | O14: {=IF(ISBLANK(N14),"",XLOOKUP(N14, 'Device Wattages'!$A$2:$A$55, 'Device Wattages'!$E$2:$E$55))} | Q14: {=IF(ISBLANK(P14),"",XLOOKUP(P14, 'Device Wattages'!$A$2:$A$55, 'Device Wattages'!$E$2:$E$55))} | S14: {=IF(ISBLANK(R14),"",XLOOKUP(R14, 'Device Wattages'!$A$2:$A$55, 'Device Wattages'!$E$2:$E$55))} | U14: {=IF(ISBLANK(T14),"",XLOOKUP(T14, 'Device Wattages'!$A$2:$A$55, 'Device Wattages'!$E$2:$E$55))} | W14: {=IF(ISBLANK(V14),"",XLOOKUP(V14, 'Device Wattages'!$A$2:$A$55, 'Device Wattages'!$E$2:$E$55))} | Y14: {=IF(ISBLANK(X14),"",XLOOKUP(X14, 'Device Wattages'!$A$2:$A$55, 'Device Wattages'!$E$2:$E$55))}
A15: T | B15: {=IF(ISBLANK(A15),"",XLOOKUP(A15, Floors!$A$2:$A$6, Floors!$B$2:$B$6))} -> Top floor | C15: BR | D15: {=IF(ISBLANK(C15),"",XLOOKUP(C15, Rooms!$A$2:$A$29, Rooms!$B$2:$B$29))} -> Bonus Room | E15: HP04 | F15: =IF(ISBLANK(E15),"",A15&"-"&C15&"-"&E15) -> T-BR-HP04 | G15: Mini Split | I15: =IF(ISBLANK(H15),"",VLOOKUP(H15,Breakers!$B$2:$C$44,2)) | J15: =CHAR(10004) -> ✔ | K15: =+M15+O15+Q15+S15+U15+W15+Y15 -> 3600 | L15: Heat Pump Mini Split | M15: {=IF(ISBLANK(L15),"",XLOOKUP(L15, 'Device Wattages'!$A$2:$A$55, 'Device Wattages'!$E$2:$E$55))} -> 3600 | O15: {=IF(ISBLANK(N15),"",XLOOKUP(N15, 'Device Wattages'!$A$2:$A$55, 'Device Wattages'!$E$2:$E$55))} | Q15: {=IF(ISBLANK(P15),"",XLOOKUP(P15, 'Device Wattages'!$A$2:$A$55, 'Device Wattages'!$E$2:$E$55))} | S15: {=IF(ISBLANK(R15),"",XLOOKUP(R15, 'Device Wattages'!$A$2:$A$55, 'Device Wattages'!$E$2:$E$55))} | U15: {=IF(ISBLANK(T15),"",XLOOKUP(T15, 'Device Wattages'!$A$2:$A$55, 'Device Wattages'!$E$2:$E$55))} | W15: {=IF(ISBLANK(V15),"",XLOOKUP(V15, 'Device Wattages'!$A$2:$A$55, 'Device Wattages'!$E$2:$E$55))} | Y15: {=IF(ISBLANK(X15),"",XLOOKUP(X15, 'Device Wattages'!$A$2:$A$55, 'Device Wattages'!$E$2:$E$55))}
A16: T | B16: {=IF(ISBLANK(A16),"",XLOOKUP(A16, FloorsTbl[Floor], FloorsTbl[Floor name]))} -> Top floor | C16: BR | D16: {=IF(ISBLANK(C16),"",XLOOKUP(C16, RoomsTbl[Room], RoomsTbl[Room Name]))} -> Bonus Room | E16: O01 | F16: =IF(ISBLANK(E16),"",A16&"-"&C16&"-"&E16) -> T-BR-O01 | G16: Outlet right front | H16: M11R | I16: =IF(ISBLANK(H16),"",VLOOKUP(H16,Breakers!$B$2:$C$44,2)) -> Main | J16: =CHAR(10004) -> ✔ | K16: =+M16+O16+Q16+S16+U16+W16+Y16 -> 30 | L16: LED Lamp | M16: {=IF(ISBLANK(L16),"",XLOOKUP(L16, DeviceWattagesTbl[Device], DeviceWattagesTbl[Power]))} -> 30 | O16: {=IF(ISBLANK(N16),"",XLOOKUP(N16, DeviceWattagesTbl[Device], DeviceWattagesTbl[Power]))} | Q16: {=IF(ISBLANK(P16),"",XLOOKUP(P16, DeviceWattagesTbl[Device], DeviceWattagesTbl[Power]))} | S16: {=IF(ISBLANK(R16),"",XLOOKUP(R16, DeviceWattagesTbl[Device], DeviceWattagesTbl[Power]))} | U16: {=IF(ISBLANK(T16),"",XLOOKUP(T16, DeviceWattagesTbl[Device], DeviceWattagesTbl[Power]))} | W16: {=IF(ISBLANK(V16),"",XLOOKUP(V16, DeviceWattagesTbl[Device], DeviceWattagesTbl[Power]))} | Y16: {=IF(ISBLANK(X16),"",XLOOKUP(X16, DeviceWattagesTbl[Device], DeviceWattagesTbl[Power]))}
A17: T | B17: {=IF(ISBLANK(A17),"",XLOOKUP(A17, FloorsTbl[Floor], FloorsTbl[Floor name]))} -> Top floor | C17: La | D17: {=IF(ISBLANK(C17),"",XLOOKUP(C17, RoomsTbl[Room], RoomsTbl[Room Name]))} -> Laundry | E17: O02 | F17: =IF(ISBLANK(E17),"",A17&"-"&C17&"-"&E17) -> T-La-O02 | G17: Outlet Washer | H17: M12L | I17: =IF(ISBLANK(H17),"",VLOOKUP(H17,Breakers!$B$2:$C$44,2)) -> Main | J17: =CHAR(10004) -> ✔ | K17: =+M17+O17+Q17+S17+U17+W17+Y17 -> #N/A | L17: Washer | M17: {=IF(ISBLANK(L17),"",XLOOKUP(L17, DeviceWattagesTbl[Device], DeviceWattagesTbl[Power]))} -> #N/A | O17: {=IF(ISBLANK(N17),"",XLOOKUP(N17, DeviceWattagesTbl[Device], DeviceWattagesTbl[Power]))} | Q17: {=IF(ISBLANK(P17),"",XLOOKUP(P17, DeviceWattagesTbl[Device], DeviceWattagesTbl[Power]))} | S17: {=IF(ISBLANK(R17),"",XLOOKUP(R17, DeviceWattagesTbl[Device], DeviceWattagesTbl[Power]))} | U17: {=IF(ISBLANK(T17),"",XLOOKUP(T17, DeviceWattagesTbl[Device], DeviceWattagesTbl[Power]))} | W17: {=IF(ISBLANK(V17),"",XLOOKUP(V17, DeviceWattagesTbl[Device], DeviceWattagesTbl[Power]))} | Y17: {=IF(ISBLANK(X17),"",XLOOKUP(X17, DeviceWattagesTbl[Device], DeviceWattagesTbl[Power]))}
A18: T | B18: {=IF(ISBLANK(A18),"",XLOOKUP(A18, FloorsTbl[Floor], FloorsTbl[Floor name]))} -> Top floor | C18: Ha | D18: {=IF(ISBLANK(C18),"",XLOOKUP(C18, RoomsTbl[Room], RoomsTbl[Room Name]))} -> Hallway | E18: O01 | F18: =IF(ISBLANK(E18),"",A18&"-"&C18&"-"&E18) -> T-Ha-O01 | G18: Outlet front middle | H18: M14L | I18: =IF(ISBLANK(H18),"",VLOOKUP(H18,Breakers!$B$2:$C$44,2)) -> Main | J18: =CHAR(10004) -> ✔ | K18: =+M18+O18+Q18+S18+U18+W18+Y18 -> 0 | M18: {=IF(ISBLANK(L18),"",XLOOKUP(L18, DeviceWattagesTbl[Device], DeviceWattagesTbl[Power]))} | O18: {=IF(ISBLANK(N18),"",XLOOKUP(N18, DeviceWattagesTbl[Device], DeviceWattagesTbl[Power]))} | Q18: {=IF(ISBLANK(P18),"",XLOOKUP(P18, DeviceWattagesTbl[Device], DeviceWattagesTbl[Power]))} | S18: {=IF(ISBLANK(R18),"",XLOOKUP(R18, DeviceWattagesTbl[Device], DeviceWattagesTbl[Power]))} | U18: {=IF(ISBLANK(T18),"",XLOOKUP(T18, DeviceWattagesTbl[Device], DeviceWattagesTbl[Power]))} | W18: {=IF(ISBLANK(V18),"",XLOOKUP(V18, DeviceWattagesTbl[Device], DeviceWattagesTbl[Power]))} | Y18: {=IF(ISBLANK(X18),"",XLOOKUP(X18, DeviceWattagesTbl[Device], DeviceWattagesTbl[Power]))}
A19: T | B19: {=IF(ISBLANK(A19),"",XLOOKUP(A19, FloorsTbl[Floor], FloorsTbl[Floor name]))} -> Top floor | C19: Ha | D19: {=IF(ISBLANK(C19),"",XLOOKUP(C19, RoomsTbl[Room], RoomsTbl[Room Name]))} -> Hallway | E19: L01 | F19: =IF(ISBLANK(E19),"",A19&"-"&C19&"-"&E19) -> T-Ha-L01 | G19: Lights track | H19: M14L | I19: =IF(ISBLANK(H19),"",VLOOKUP(H19,Breakers!$B$2:$C$44,2)) -> Main | J19: =CHAR(10004) -> ✔ | K19: =+M19+O19+Q19+S19+U19+W19+Y19 -> 90 | L19: LED Lamp | M19: {=IF(ISBLANK(L19),"",XLOOKUP(L19, DeviceWattagesTbl[Device], DeviceWattagesTbl[Power]))} -> 30 | N19: LED Lamp | O19: {=IF(ISBLANK(N19),"",XLOOKUP(N19, DeviceWattagesTbl[Device], DeviceWattagesTbl[Power]))} -> 30 | P19: LED Lamp | Q19: {=IF(ISBLANK(P19),"",XLOOKUP(P19, DeviceWattagesTbl[Device], DeviceWattagesTbl[Power]))} -> 30 | S19: {=IF(ISBLANK(R19),"",XLOOKUP(R19, DeviceWattagesTbl[Device], DeviceWattagesTbl[Power]))} | U19: {=IF(ISBLANK(T19),"",XLOOKUP(T19, DeviceWattagesTbl[Device], DeviceWattagesTbl[Power]))} | W19: {=IF(ISBLANK(V19),"",XLOOKUP(V19, DeviceWattagesTbl[Device], DeviceWattagesTbl[Power]))} | Y19: {=IF(ISBLANK(X19),"",XLOOKUP(X19, DeviceWattagesTbl[Device], DeviceWattagesTbl[Power]))}
A20: T | B20: {=IF(ISBLANK(A20),"",XLOOKUP(A20, FloorsTbl[Floor], FloorsTbl[Floor name]))} -> Top floor | C20: Mx | D20: {=IF(ISBLANK(C20),"",XLOOKUP(C20, RoomsTbl[Room], RoomsTbl[Room Name]))} -> Max's bedroom | E20: O05 | F20: =IF(ISBLANK(E20),"",A20&"-"&C20&"-"&E20) -> T-Mx-O05 | G20: Outlet right | H20: M14L | I20: {=IF(ISBLANK(H20),"",XLOOKUP(H20, BreakersTbl[Breaker Name], BreakersTbl[Breaker Box Name]))} -> Main | J20: =CHAR(10004) -> ✔ | K20: =+M20+O20+Q20+S20+U20+W20+Y20 -> 0 | M20: {=IF(ISBLANK(L20),"",XLOOKUP(L20, DeviceWattagesTbl[Device], DeviceWattagesTbl[Power]))} | O20: {=IF(ISBLANK(N20),"",XLOOKUP(N20, DeviceWattagesTbl[Device], DeviceWattagesTbl[Power]))} | Q20: {=IF(ISBLANK(P20),"",XLOOKUP(P20, DeviceWattagesTbl[Device], DeviceWattagesTbl[Power]))} | S20: {=IF(ISBLANK(R20),"",XLOOKUP(R20, DeviceWattagesTbl[Device], DeviceWattagesTbl[Power]))} | U20: {=IF(ISBLANK(T20),"",XLOOKUP(T20, DeviceWattagesTbl[Device], DeviceWattagesTbl[Power]))} | W20: {=IF(ISBLANK(V20),"",XLOOKUP(V20, DeviceWattagesTbl[Device], DeviceWattagesTbl[Power]))} | Y20: {=IF(ISBLANK(X20),"",XLOOKUP(X20, DeviceWattagesTbl[Device], DeviceWattagesTbl[Power]))}
A21: T | B21: {=IF(ISBLANK(A21),"",XLOOKUP(A21, FloorsTbl[Floor], FloorsTbl[Floor name]))} -> Top floor | C21: Mx | D21: {=IF(ISBLANK(C21),"",XLOOKUP(C21, RoomsTbl[Room], RoomsTbl[Room Name]))} -> Max's bedroom | E21: O04 | F21: =IF(ISBLANK(E21),"",A21&"-"&C21&"-"&E21) -> T-Mx-O04 | G21: Outlet front | H21: M14L | I21: {=IF(ISBLANK(H21),"",XLOOKUP(H21, BreakersTbl[Breaker Name], BreakersTbl[Breaker Box Name]))} -> Main | J21: =CHAR(10004) -> ✔ | K21: =+M21+O21+Q21+S21+U21+W21+Y21 -> 0 | M21: {=IF(ISBLANK(L21),"",XLOOKUP(L21, DeviceWattagesTbl[Device], DeviceWattagesTbl[Power]))} | O21: {=IF(ISBLANK(N21),"",XLOOKUP(N21, DeviceWattagesTbl[Device], DeviceWattagesTbl[Power]))} | Q21: {=IF(ISBLANK(P21),"",XLOOKUP(P21, DeviceWattagesTbl[Device], DeviceWattagesTbl[Power]))} | S21: {=IF(ISBLANK(R21),"",XLOOKUP(R21, DeviceWattagesTbl[Device], DeviceWattagesTbl[Power]))} | U21: {=IF(ISBLANK(T21),"",XLOOKUP(T21, DeviceWattagesTbl[Device], DeviceWattagesTbl[Power]))} | W21: {=IF(ISBLANK(V21),"",XLOOKUP(V21, DeviceWattagesTbl[Device], DeviceWattagesTbl[Power]))} | Y21: {=IF(ISBLANK(X21),"",XLOOKUP(X21, DeviceWattagesTbl[Device], DeviceWattagesTbl[Power]))}
A22: T | B22: {=IF(ISBLANK(A22),"",XLOOKUP(A22, FloorsTbl[Floor], FloorsTbl[Floor name]))} -> Top floor | C22: Mx | D22: {=IF(ISBLANK(C22),"",XLOOKUP(C22, RoomsTbl[Room], RoomsTbl[Room Name]))} -> Max's bedroom | E22: O03 | F22: =IF(ISBLANK(E22),"",A22&"-"&C22&"-"&E22) -> T-Mx-O03 | G22: Outlet left front | H22: M14L | I22: {=IF(ISBLANK(H22),"",XLOOKUP(H22, BreakersTbl[Breaker Name], BreakersTbl[Breaker Box Name]))} -> Main | J22: =CHAR(10004) -> ✔ | K22: =+M22+O22+Q22+S22+U22+W22+Y22 -> 30 | L22: LED Lamp | M22: {=IF(ISBLANK(L22),"",XLOOKUP(L22, DeviceWattagesTbl[Device], DeviceWattagesTbl[Power]))} -> 30 | O22: {=IF(ISBLANK(N22),"",XLOOKUP(N22, DeviceWattagesTbl[Device], DeviceWattagesTbl[Power]))} | Q22: {=IF(ISBLANK(P22),"",XLOOKUP(P22, DeviceWattagesTbl[Device], DeviceWattagesTbl[Power]))} | S22: {=IF(ISBLANK(R22),"",XLOOKUP(R22, DeviceWattagesTbl[Device], DeviceWattagesTbl[Power]))} | U22: {=IF(ISBLANK(T22),"",XLOOKUP(T22, DeviceWattagesTbl[Device], DeviceWattagesTbl[Power]))} | W22: {=IF(ISBLANK(V22),"",XLOOKUP(V22, DeviceWattagesTbl[Device], DeviceWattagesTbl[Power]))} | Y22: {=IF(ISBLANK(X22),"",XLOOKUP(X22, DeviceWattagesTbl[Device], DeviceWattagesTbl[Power]))}
A23: T | B23: {=IF(ISBLANK(A23),"",XLOOKUP(A23, FloorsTbl[Floor], FloorsTbl[Floor name]))} -> Top floor | C23: Mx | D23: {=IF(ISBLANK(C23),"",XLOOKUP(C23, RoomsTbl[Room], RoomsTbl[Room Name]))} -> Max's bedroom | E23: O02 | F23: =IF(ISBLANK(E23),"",A23&"-"&C23&"-"&E23) -> T-Mx-O02 | G23: Outlet left back | H23: M14L | I23: {=IF(ISBLANK(H23),"",XLOOKUP(H23, BreakersTbl[Breaker Name], BreakersTbl[Breaker Box Name]))} -> Main | J23: =CHAR(10004) -> ✔ | K23: =+M23+O23+Q23+S23+U23+W23+Y23 -> 30 | L23: LED Lamp | M23: {=IF(ISBLANK(L23),"",XLOOKUP(L23, DeviceWattagesTbl[Device], DeviceWattagesTbl[Power]))} -> 30 | O23: {=IF(ISBLANK(N23),"",XLOOKUP(N23, DeviceWattagesTbl[Device], DeviceWattagesTbl[Power]))} | Q23: {=IF(ISBLANK(P23),"",XLOOKUP(P23, DeviceWattagesTbl[Device], DeviceWattagesTbl[Power]))} | S23: {=IF(ISBLANK(R23),"",XLOOKUP(R23, DeviceWattagesTbl[Device], DeviceWattagesTbl[Power]))} | U23: {=IF(ISBLANK(T23),"",XLOOKUP(T23, DeviceWattagesTbl[Device], DeviceWattagesTbl[Power]))} | W23: {=IF(ISBLANK(V23),"",XLOOKUP(V23, DeviceWattagesTbl[Device], DeviceWattagesTbl[Power]))} | Y23: {=IF(ISBLANK(X23),"",XLOOKUP(X23, DeviceWattagesTbl[Device], DeviceWattagesTbl[Power]))}
A24: T | B24: {=IF(ISBLANK(A24),"",XLOOKUP(A24, FloorsTbl[Floor], FloorsTbl[Floor name]))} -> Top floor | C24: Mx | D24: {=IF(ISBLANK(C24),"",XLOOKUP(C24, RoomsTbl[Room], RoomsTbl[Room Name]))} -> Max's bedroom | E24: O01 | F24: =IF(ISBLANK(E24),"",A24&"-"&C24&"-"&E24) -> T-Mx-O01 | G24: Outlet back | H24: M14L | I24: {=IF(ISBLANK(H24),"",XLOOKUP(H24, BreakersTbl[Breaker Name], BreakersTbl[Breaker Box Name]))} -> Main | J24: =CHAR(10004) -> ✔ | K24: =+M24+O24+Q24+S24+U24+W24+Y24 -> 0 | M24: {=IF(ISBLANK(L24),"",XLOOKUP(L24, DeviceWattagesTbl[Device], DeviceWattagesTbl[Power]))} | O24: {=IF(ISBLANK(N24),"",XLOOKUP(N24, DeviceWattagesTbl[Device], DeviceWattagesTbl[Power]))} | Q24: {=IF(ISBLANK(P24),"",XLOOKUP(P24, DeviceWattagesTbl[Device], DeviceWattagesTbl[Power]))} | S24: {=IF(ISBLANK(R24),"",XLOOKUP(R24, DeviceWattagesTbl[Device], DeviceWattagesTbl[Power]))} | U24: {=IF(ISBLANK(T24),"",XLOOKUP(T24, DeviceWattagesTbl[Device], DeviceWattagesTbl[Power]))} | W24: {=IF(ISBLANK(V24),"",XLOOKUP(V24, DeviceWattagesTbl[Device], DeviceWattagesTbl[Power]))} | Y24: {=IF(ISBLANK(X24),"",XLOOKUP(X24, DeviceWattagesTbl[Device], DeviceWattagesTbl[Power]))}
A25: T | B25: {=IF(ISBLANK(A25),"",XLOOKUP(A25, FloorsTbl[Floor], FloorsTbl[Floor name]))} -> Top floor | C25: Mx | D25: {=IF(ISBLANK(C25),"",XLOOKUP(C25, RoomsTbl[Room], RoomsTbl[Room Name]))} -> Max's bedroom | E25: L01 | F25: =IF(ISBLANK(E25),"",A25&"-"&C25&"-"&E25) -> T-Mx-L01 | G25: Light over bed | H25: M14L | I25: {=IF(ISBLANK(H25),"",XLOOKUP(H25, BreakersTbl[Breaker Name], BreakersTbl[Breaker Box Name]))} -> Main | J25: =CHAR(10004) -> ✔ | K25: =+M25+O25+Q25+S25+U25+W25+Y25 -> 30 | L25: LED Lamp | M25: {=IF(ISBLANK(L25),"",XLOOKUP(L25, DeviceWattagesTbl[Device], DeviceWattagesTbl[Power]))} -> 30 | O25: {=IF(ISBLANK(N25),"",XLOOKUP(N25, DeviceWattagesTbl[Device], DeviceWattagesTbl[Power]))} | Q25: {=IF(ISBLANK(P25),"",XLOOKUP(P25, DeviceWattagesTbl[Device], DeviceWattagesTbl[Power]))} | S25: {=IF(ISBLANK(R25),"",XLOOKUP(R25, DeviceWattagesTbl[Device], DeviceWattagesTbl[Power]))} | U25: {=IF(ISBLANK(T25),"",XLOOKUP(T25, DeviceWattagesTbl[Device], DeviceWattagesTbl[Power]))} | W25: {=IF(ISBLANK(V25),"",XLOOKUP(V25, DeviceWattagesTbl[Device], DeviceWattagesTbl[Power]))} | Y25: {=IF(ISBLANK(X25),"",XLOOKUP(X25, DeviceWattagesTbl[Device], DeviceWattagesTbl[Power]))}
A26: T | B26: {=IF(ISBLANK(A26),"",XLOOKUP(A26, FloorsTbl[Floor], FloorsTbl[Floor name]))} -> Top floor | C26: BR | D26: {=IF(ISBLANK(C26),"",XLOOKUP(C26, RoomsTbl[Room], RoomsTbl[Room Name]))} -> Bonus Room | E26: L01 | F26: =IF(ISBLANK(E26),"",A26&"-"&C26&"-"&E26) -> T-BR-L01 | G26: Light ceiling | H26: M14R | I26: Main | J26: =CHAR(10004) -> ✔ | K26: =+M26+O26+Q26+S26+U26+W26+Y26 -> #N/A | L26: Can't test | M26: {=IF(ISBLANK(L26),"",XLOOKUP(L26, DeviceWattagesTbl[Device], DeviceWattagesTbl[Power]))} -> #N/A | O26: {=IF(ISBLANK(N26),"",XLOOKUP(N26, DeviceWattagesTbl[Device], DeviceWattagesTbl[Power]))} | Q26: {=IF(ISBLANK(P26),"",XLOOKUP(P26, DeviceWattagesTbl[Device], DeviceWattagesTbl[Power]))} | S26: {=IF(ISBLANK(R26),"",XLOOKUP(R26, DeviceWattagesTbl[Device], DeviceWattagesTbl[Power]))} | U26: {=IF(ISBLANK(T26),"",XLOOKUP(T26, DeviceWattagesTbl[Device], DeviceWattagesTbl[Power]))} | W26: {=IF(ISBLANK(V26),"",XLOOKUP(V26, DeviceWattagesTbl[Device], DeviceWattagesTbl[Power]))} | Y26: {=IF(ISBLANK(X26),"",XLOOKUP(X26, DeviceWattagesTbl[Device], DeviceWattagesTbl[Power]))}
A27: T | B27: {=IF(ISBLANK(A27),"",XLOOKUP(A27, FloorsTbl[Floor], FloorsTbl[Floor name]))} -> Top floor | C27: La | D27: {=IF(ISBLANK(C27),"",XLOOKUP(C27, RoomsTbl[Room], RoomsTbl[Room Name]))} -> Laundry | E27: L01 | F27: =IF(ISBLANK(E27),"",A27&"-"&C27&"-"&E27) -> T-La-L01 | G27: Light ceiling | H27: M14R | I27: =IF(ISBLANK(H27),"",VLOOKUP(H27,Breakers!$B$2:$C$44,2)) -> Main | J27: =CHAR(10004) -> ✔ | K27: =+M27+O27+Q27+S27+U27+W27+Y27 -> 60 | L27: LED Lamp | M27: {=IF(ISBLANK(L27),"",XLOOKUP(L27, DeviceWattagesTbl[Device], DeviceWattagesTbl[Power]))} -> 30 | N27: LED Lamp | O27: {=IF(ISBLANK(N27),"",XLOOKUP(N27, DeviceWattagesTbl[Device], DeviceWattagesTbl[Power]))} -> 30 | Q27: {=IF(ISBLANK(P27),"",XLOOKUP(P27, DeviceWattagesTbl[Device], DeviceWattagesTbl[Power]))} | S27: {=IF(ISBLANK(R27),"",XLOOKUP(R27, DeviceWattagesTbl[Device], DeviceWattagesTbl[Power]))} | U27: {=IF(ISBLANK(T27),"",XLOOKUP(T27, DeviceWattagesTbl[Device], DeviceWattagesTbl[Power]))} | W27: {=IF(ISBLANK(V27),"",XLOOKUP(V27, DeviceWattagesTbl[Device], DeviceWattagesTbl[Power]))} | Y27: {=IF(ISBLANK(X27),"",XLOOKUP(X27, DeviceWattagesTbl[Device], DeviceWattagesTbl[Power]))}
A28: T | B28: {=IF(ISBLANK(A28),"",XLOOKUP(A28, FloorsTbl[Floor], FloorsTbl[Floor name]))} -> Top floor | C28: Th | D28: {=IF(ISBLANK(C28),"",XLOOKUP(C28, RoomsTbl[Room], RoomsTbl[Room Name]))} -> Thurston's bedroom | E28: O05 | F28: =IF(ISBLANK(E28),"",A28&"-"&C28&"-"&E28) -> T-Th-O05 | G28: Outlet right front | H28: M14R | I28: {=IF(ISBLANK(H28),"",XLOOKUP(H28, BreakersTbl[Breaker Name], BreakersTbl[Breaker Box Name]))} -> Main | J28: =CHAR(10004) -> ✔ | K28: =+M28+O28+Q28+S28+U28+W28+Y28 -> 150 | L28: LED Lamp | M28: {=IF(ISBLANK(L28),"",XLOOKUP(L28, DeviceWattagesTbl[Device], DeviceWattagesTbl[Power]))} -> 30 | N28: Computer Small | O28: {=IF(ISBLANK(N28),"",XLOOKUP(N28, DeviceWattagesTbl[Device], DeviceWattagesTbl[Power]))} -> 120 | Q28: {=IF(ISBLANK(P28),"",XLOOKUP(P28, DeviceWattagesTbl[Device], DeviceWattagesTbl[Power]))} | S28: {=IF(ISBLANK(R28),"",XLOOKUP(R28, DeviceWattagesTbl[Device], DeviceWattagesTbl[Power]))} | U28: {=IF(ISBLANK(T28),"",XLOOKUP(T28, DeviceWattagesTbl[Device], DeviceWattagesTbl[Power]))} | W28: {=IF(ISBLANK(V28),"",XLOOKUP(V28, DeviceWattagesTbl[Device], DeviceWattagesTbl[Power]))} | Y28: {=IF(ISBLANK(X28),"",XLOOKUP(X28, DeviceWattagesTbl[Device], DeviceWattagesTbl[Power]))}
A29: T | B29: {=IF(ISBLANK(A29),"",XLOOKUP(A29, FloorsTbl[Floor], FloorsTbl[Floor name]))} -> Top floor | C29: Th | D29: {=IF(ISBLANK(C29),"",XLOOKUP(C29, RoomsTbl[Room], RoomsTbl[Room Name]))} -> Thurston's bedroom | E29: O04 | F29: =IF(ISBLANK(E29),"",A29&"-"&C29&"-"&E29) -> T-Th-O04 | G29: Outlet right back | H29: M14R | I29: {=IF(ISBLANK(H29),"",XLOOKUP(H29, BreakersTbl[Breaker Name], BreakersTbl[Breaker Box Name]))} -> Main | J29: =CHAR(10004) -> ✔ | K29: =+M29+O29+Q29+S29+U29+W29+Y29 -> 0 | M29: {=IF(ISBLANK(L29),"",XLOOKUP(L29, DeviceWattagesTbl[Device], DeviceWattagesTbl[Power]))} | O29: {=IF(ISBLANK(N29),"",XLOOKUP(N29, DeviceWattagesTbl[Device], DeviceWattagesTbl[Power]))} | Q29: {=IF(ISBLANK(P29),"",XLOOKUP(P29, DeviceWattagesTbl[Device], DeviceWattagesTbl[Power]))} | S29: {=IF(ISBLANK(R29),"",XLOOKUP(R29, DeviceWattagesTbl[Device], DeviceWattagesTbl[Power]))} | U29: {=IF(ISBLANK(T29),"",XLOOKUP(T29, DeviceWattagesTbl[Device], DeviceWattagesTbl[Power]))} | W29: {=IF(ISBLANK(V29),"",XLOOKUP(V29, DeviceWattagesTbl[Device], DeviceWattagesTbl[Power]))} | Y29: {=IF(ISBLANK(X29),"",XLOOKUP(X29, DeviceWattagesTbl[Device], DeviceWattagesTbl[Power]))}
A30: T | B30: {=IF(ISBLANK(A30),"",XLOOKUP(A30, FloorsTbl[Floor], FloorsTbl[Floor name]))} -> Top floor | C30: Th | D30: {=IF(ISBLANK(C30),"",XLOOKUP(C30, RoomsTbl[Room], RoomsTbl[Room Name]))} -> Thurston's bedroom | E30: O03 | F30: =IF(ISBLANK(E30),"",A30&"-"&C30&"-"&E30) -> T-Th-O03 | G30: Outlet back | H30: M14R | I30: {=IF(ISBLANK(H30),"",XLOOKUP(H30, BreakersTbl[Breaker Name], BreakersTbl[Breaker Box Name]))} -> Main | J30: =CHAR(10004) -> ✔ | K30: =+M30+O30+Q30+S30+U30+W30+Y30 -> 0 | M30: {=IF(ISBLANK(L30),"",XLOOKUP(L30, DeviceWattagesTbl[Device], DeviceWattagesTbl[Power]))} | O30: {=IF(ISBLANK(N30),"",XLOOKUP(N30, DeviceWattagesTbl[Device], DeviceWattagesTbl[Power]))} | Q30: {=IF(ISBLANK(P30),"",XLOOKUP(P30, DeviceWattagesTbl[Device], DeviceWattagesTbl[Power]))} | S30: {=IF(ISBLANK(R30),"",XLOOKUP(R30, DeviceWattagesTbl[Device], DeviceWattagesTbl[Power]))} | U30: {=IF(ISBLANK(T30),"",XLOOKUP(T30, DeviceWattagesTbl[Device], DeviceWattagesTbl[Power]))} | W30: {=IF(ISBLANK(V30),"",XLOOKUP(V30, DeviceWattagesTbl[Device], DeviceWattagesTbl[Power]))} | Y30: {=IF(ISBLANK(X30),"",XLOOKUP(X30, DeviceWattagesTbl[Device], DeviceWattagesTbl[Power]))}
A31: T | B31: {=IF(ISBLANK(A31),"",XLOOKUP(A31, FloorsTbl[Floor], FloorsTbl[Floor name]))} -> Top floor | C31: Th | D31: {=IF(ISBLANK(C31),"",XLOOKUP(C31, RoomsTbl[Room], RoomsTbl[Room Name]))} -> Thurston's bedroom | E31: O02 | F31: =IF(ISBLANK(E31),"",A31&"-"&C31&"-"&E31) -> T-Th-O02 | G31: Outlet under computer desk | H31: M14R | I31: {=IF(ISBLANK(H31),"",XLOOKUP(H31, BreakersTbl[Breaker Name], BreakersTbl[Breaker Box Name]))} -> Main | J31: =CHAR(10004) -> ✔ | K31: =+M31+O31+Q31+S31+U31+W31+Y31 -> 290 | L31: LED Lamp | M31: {=IF(ISBLANK(L31),"",XLOOKUP(L31, DeviceWattagesTbl[Device], DeviceWattagesTbl[Power]))} -> 30 | N31: Computer Large | O31: {=IF(ISBLANK(N31),"",XLOOKUP(N31, DeviceWattagesTbl[Device], DeviceWattagesTbl[Power]))} -> 240 | P31: Ipad | Q31: {=IF(ISBLANK(P31),"",XLOOKUP(P31, DeviceWattagesTbl[Device], DeviceWattagesTbl[Power]))} -> 20 | S31: {=IF(ISBLANK(R31),"",XLOOKUP(R31, DeviceWattagesTbl[Device], DeviceWattagesTbl[Power]))} | U31: {=IF(ISBLANK(T31),"",XLOOKUP(T31, DeviceWattagesTbl[Device], DeviceWattagesTbl[Power]))} | W31: {=IF(ISBLANK(V31),"",XLOOKUP(V31, DeviceWattagesTbl[Device], DeviceWattagesTbl[Power]))} | Y31: {=IF(ISBLANK(X31),"",XLOOKUP(X31, DeviceWattagesTbl[Device], DeviceWattagesTbl[Power]))}
A32: T | B32: {=IF(ISBLANK(A32),"",XLOOKUP(A32, FloorsTbl[Floor], FloorsTbl[Floor name]))} -> Top floor | C32: Th | D32: {=IF(ISBLANK(C32),"",XLOOKUP(C32, RoomsTbl[Room], RoomsTbl[Room Name]))} -> Thurston's bedroom | E32: O01 | F32: =IF(ISBLANK(E32),"",A32&"-"&C32&"-"&E32) -> T-Th-O01 | G32: Outlet front left | H32: M14R | I32: {=IF(ISBLANK(H32),"",XLOOKUP(H32, BreakersTbl[Breaker Name], BreakersTbl[Breaker Box Name]))} -> Main | J32: =CHAR(10004) -> ✔ | K32: =+M32+O32+Q32+S32+U32+W32+Y32 -> 0 | M32: {=IF(ISBLANK(L32),"",XLOOKUP(L32, DeviceWattagesTbl[Device], DeviceWattagesTbl[Power]))} | O32: {=IF(ISBLANK(N32),"",XLOOKUP(N32, DeviceWattagesTbl[Device], DeviceWattagesTbl[Power]))} | Q32: {=IF(ISBLANK(P32),"",XLOOKUP(P32, DeviceWattagesTbl[Device], DeviceWattagesTbl[Power]))} | S32: {=IF(ISBLANK(R32),"",XLOOKUP(R32, DeviceWattagesTbl[Device], DeviceWattagesTbl[Power]))} | U32: {=IF(ISBLANK(T32),"",XLOOKUP(T32, DeviceWattagesTbl[Device], DeviceWattagesTbl[Power]))} | W32: {=IF(ISBLANK(V32),"",XLOOKUP(V32, DeviceWattagesTbl[Device], DeviceWattagesTbl[Power]))} | Y32: {=IF(ISBLANK(X32),"",XLOOKUP(X32, DeviceWattagesTbl[Device], DeviceWattagesTbl[Power]))}
A33: T | B33: {=IF(ISBLANK(A33),"",XLOOKUP(A33, FloorsTbl[Floor], FloorsTbl[Floor name]))} -> Top floor | C33: Th | D33: {=IF(ISBLANK(C33),"",XLOOKUP(C33, RoomsTbl[Room], RoomsTbl[Room Name]))} -> Thurston's bedroom | E33: L01 | F33: =IF(ISBLANK(E33),"",A33&"-"&C33&"-"&E33) -> T-Th-L01 | G33: Light ceiling | H33: M14L | I33: {=IF(ISBLANK(H33),"",XLOOKUP(H33, BreakersTbl[Breaker Name], BreakersTbl[Breaker Box Name]))} -> Main | J33: =CHAR(10004) -> ✔ | K33: =+M33+O33+Q33+S33+U33+W33+Y33 -> 0 | M33: {=IF(ISBLANK(L33),"",XLOOKUP(L33, DeviceWattagesTbl[Device], DeviceWattagesTbl[Power]))} | O33: {=IF(ISBLANK(N33),"",XLOOKUP(N33, DeviceWattagesTbl[Device], DeviceWattagesTbl[Power]))} | Q33: {=IF(ISBLANK(P33),"",XLOOKUP(P33, DeviceWattagesTbl[Device], DeviceWattagesTbl[Power]))} | S33: {=IF(ISBLANK(R33),"",XLOOKUP(R33, DeviceWattagesTbl[Device], DeviceWattagesTbl[Power]))} | U33: {=IF(ISBLANK(T33),"",XLOOKUP(T33, DeviceWattagesTbl[Device], DeviceWattagesTbl[Power]))} | W33: {=IF(ISBLANK(V33),"",XLOOKUP(V33, DeviceWattagesTbl[Device], DeviceWattagesTbl[Power]))} | Y33: {=IF(ISBLANK(X33),"",XLOOKUP(X33, DeviceWattagesTbl[Device], DeviceWattagesTbl[Power]))}
A34: T | B34: {=IF(ISBLANK(A34),"",XLOOKUP(A34, FloorsTbl[Floor], FloorsTbl[Floor name]))} -> Top floor | C34: GB | D34: {=IF(ISBLANK(C34),"",XLOOKUP(C34, RoomsTbl[Room], RoomsTbl[Room Name]))} -> Guest Bathroom | E34: O02 | F34: =IF(ISBLANK(E34),"",A34&"-"&C34&"-"&E34) -> T-GB-O02 | G34: Outlet under sink left | H34: M19R | I34: =IF(ISBLANK(H34),"",VLOOKUP(H34,Breakers!$B$2:$C$44,2)) -> Main | J34: =CHAR(10004) -> ✔ | K34: =+M34+O34+Q34+S34+U34+W34+Y34 -> 1000 | L34: Toto Toilet Seat | M34: {=IF(ISBLANK(L34),"",XLOOKUP(L34, DeviceWattagesTbl[Device], DeviceWattagesTbl[Power]))} -> 1000 | O34: {=IF(ISBLANK(N34),"",XLOOKUP(N34, DeviceWattagesTbl[Device], DeviceWattagesTbl[Power]))} | Q34: {=IF(ISBLANK(P34),"",XLOOKUP(P34, DeviceWattagesTbl[Device], DeviceWattagesTbl[Power]))} | S34: {=IF(ISBLANK(R34),"",XLOOKUP(R34, DeviceWattagesTbl[Device], DeviceWattagesTbl[Power]))} | U34: {=IF(ISBLANK(T34),"",XLOOKUP(T34, DeviceWattagesTbl[Device], DeviceWattagesTbl[Power]))} | W34: {=IF(ISBLANK(V34),"",XLOOKUP(V34, DeviceWattagesTbl[Device], DeviceWattagesTbl[Power]))} | Y34: {=IF(ISBLANK(X34),"",XLOOKUP(X34, DeviceWattagesTbl[Device], DeviceWattagesTbl[Power]))}
A35: T | B35: {=IF(ISBLANK(A35),"",XLOOKUP(A35, FloorsTbl[Floor], FloorsTbl[Floor name]))} -> Top floor | C35: GB | D35: {=IF(ISBLANK(C35),"",XLOOKUP(C35, RoomsTbl[Room], RoomsTbl[Room Name]))} -> Guest Bathroom | E35: O01 | F35: =IF(ISBLANK(E35),"",A35&"-"&C35&"-"&E35) -> T-GB-O01 | G35: Outlet by sink left | H35: M19R | I35: =IF(ISBLANK(H35),"",VLOOKUP(H35,Breakers!$B$2:$C$44,2)) -> Main | J35: =CHAR(10004) -> ✔ | K35: =+M35+O35+Q35+S35+U35+W35+Y35 -> 0 | M35: {=IF(ISBLANK(L35),"",XLOOKUP(L35, DeviceWattagesTbl[Device], DeviceWattagesTbl[Power]))} | O35: {=IF(ISBLANK(N35),"",XLOOKUP(N35, DeviceWattagesTbl[Device], DeviceWattagesTbl[Power]))} | Q35: {=IF(ISBLANK(P35),"",XLOOKUP(P35, DeviceWattagesTbl[Device], DeviceWattagesTbl[Power]))} | S35: {=IF(ISBLANK(R35),"",XLOOKUP(R35, DeviceWattagesTbl[Device], DeviceWattagesTbl[Power]))} | U35: {=IF(ISBLANK(T35),"",XLOOKUP(T35, DeviceWattagesTbl[Device], DeviceWattagesTbl[Power]))} | W35: {=IF(ISBLANK(V35),"",XLOOKUP(V35, DeviceWattagesTbl[Device], DeviceWattagesTbl[Power]))} | Y35: {=IF(ISBLANK(X35),"",XLOOKUP(X35, DeviceWattagesTbl[Device], DeviceWattagesTbl[Power]))}
A36: T | B36: {=IF(ISBLANK(A36),"",XLOOKUP(A36, FloorsTbl[Floor], FloorsTbl[Floor name]))} -> Top floor | C36: GB | D36: {=IF(ISBLANK(C36),"",XLOOKUP(C36, RoomsTbl[Room], RoomsTbl[Room Name]))} -> Guest Bathroom | E36: L10 | F36: =IF(ISBLANK(E36),"",A36&"-"&C36&"-"&E36) -> T-GB-L10 | G36: Light above sink | H36: M19R | I36: =IF(ISBLANK(H36),"",VLOOKUP(H36,Breakers!$B$2:$C$44,2)) -> Main | J36: =CHAR(10004) -> ✔ | K36: =+M36+O36+Q36+S36+U36+W36+Y36 -> 60 | L36: LED Lamp | M36: {=IF(ISBLANK(L36),"",XLOOKUP(L36, DeviceWattagesTbl[Device], DeviceWattagesTbl[Power]))} -> 30 | N36: LED Lamp | O36: {=IF(ISBLANK(N36),"",XLOOKUP(N36, DeviceWattagesTbl[Device], DeviceWattagesTbl[Power]))} -> 30 | Q36: {=IF(ISBLANK(P36),"",XLOOKUP(P36, DeviceWattagesTbl[Device], DeviceWattagesTbl[Power]))} | S36: {=IF(ISBLANK(R36),"",XLOOKUP(R36, DeviceWattagesTbl[Device], DeviceWattagesTbl[Power]))} | U36: {=IF(ISBLANK(T36),"",XLOOKUP(T36, DeviceWattagesTbl[Device], DeviceWattagesTbl[Power]))} | W36: {=IF(ISBLANK(V36),"",XLOOKUP(V36, DeviceWattagesTbl[Device], DeviceWattagesTbl[Power]))} | Y36: {=IF(ISBLANK(X36),"",XLOOKUP(X36, DeviceWattagesTbl[Device], DeviceWattagesTbl[Power]))}
A37: T | B37: {=IF(ISBLANK(A37),"",XLOOKUP(A37, FloorsTbl[Floor], FloorsTbl[Floor name]))} -> Top floor | C37: Ha | D37: {=IF(ISBLANK(C37),"",XLOOKUP(C37, RoomsTbl[Room], RoomsTbl[Room Name]))} -> Hallway | E37: L02 | F37: =IF(ISBLANK(E37),"",A37&"-"&C37&"-"&E37) -> T-Ha-L02 | G37: Lights in stairwell down | H37: M19R | I37: =IF(ISBLANK(H37),"",VLOOKUP(H37,Breakers!$B$2:$C$44,2)) -> Main | J37: =CHAR(10004) -> ✔ | K37: =+M37+O37+Q37+S37+U37+W37+Y37 -> 0 | M37: {=IF(ISBLANK(L37),"",XLOOKUP(L37, DeviceWattagesTbl[Device], DeviceWattagesTbl[Power]))} | O37: {=IF(ISBLANK(N37),"",XLOOKUP(N37, DeviceWattagesTbl[Device], DeviceWattagesTbl[Power]))} | Q37: {=IF(ISBLANK(P37),"",XLOOKUP(P37, DeviceWattagesTbl[Device], DeviceWattagesTbl[Power]))} | S37: {=IF(ISBLANK(R37),"",XLOOKUP(R37, DeviceWattagesTbl[Device], DeviceWattagesTbl[Power]))} | U37: {=IF(ISBLANK(T37),"",XLOOKUP(T37, DeviceWattagesTbl[Device], DeviceWattagesTbl[Power]))} | W37: {=IF(ISBLANK(V37),"",XLOOKUP(V37, DeviceWattagesTbl[Device], DeviceWattagesTbl[Power]))} | Y37: {=IF(ISBLANK(X37),"",XLOOKUP(X37, DeviceWattagesTbl[Device], DeviceWattagesTbl[Power]))}
A38: T | B38: {=IF(ISBLANK(A38),"",XLOOKUP(A38, FloorsTbl[Floor], FloorsTbl[Floor name]))} -> Top floor | C38: Ma | D38: {=IF(ISBLANK(C38),"",XLOOKUP(C38, RoomsTbl[Room], RoomsTbl[Room Name]))} -> Master Bedroom | E38: O07 | F38: =IF(ISBLANK(E38),"",A38&"-"&C38&"-"&E38) -> T-Ma-O07 | G38: Outlet right back | H38: M19R | I38: =IF(ISBLANK(H38),"",VLOOKUP(H38,Breakers!$B$2:$C$44,2)) -> Main | J38: =CHAR(10004) -> ✔ | K38: =+M38+O38+Q38+S38+U38+W38+Y38 -> 0 | M38: {=IF(ISBLANK(L38),"",XLOOKUP(L38, DeviceWattagesTbl[Device], DeviceWattagesTbl[Power]))} | O38: {=IF(ISBLANK(N38),"",XLOOKUP(N38, DeviceWattagesTbl[Device], DeviceWattagesTbl[Power]))} | Q38: {=IF(ISBLANK(P38),"",XLOOKUP(P38, DeviceWattagesTbl[Device], DeviceWattagesTbl[Power]))} | S38: {=IF(ISBLANK(R38),"",XLOOKUP(R38, DeviceWattagesTbl[Device], DeviceWattagesTbl[Power]))} | U38: {=IF(ISBLANK(T38),"",XLOOKUP(T38, DeviceWattagesTbl[Device], DeviceWattagesTbl[Power]))} | W38: {=IF(ISBLANK(V38),"",XLOOKUP(V38, DeviceWattagesTbl[Device], DeviceWattagesTbl[Power]))} | Y38: {=IF(ISBLANK(X38),"",XLOOKUP(X38, DeviceWattagesTbl[Device], DeviceWattagesTbl[Power]))}
A39: T | B39: {=IF(ISBLANK(A39),"",XLOOKUP(A39, FloorsTbl[Floor], FloorsTbl[Floor name]))} -> Top floor | C39: Ma | D39: {=IF(ISBLANK(C39),"",XLOOKUP(C39, RoomsTbl[Room], RoomsTbl[Room Name]))} -> Master Bedroom | E39: O06 | F39: =IF(ISBLANK(E39),"",A39&"-"&C39&"-"&E39) -> T-Ma-O06 | G39: Outlet TV | H39: M19R | I39: =IF(ISBLANK(H39),"",VLOOKUP(H39,Breakers!$B$2:$C$44,2)) -> Main | J39: =CHAR(10004) -> ✔ | K39: =+M39+O39+Q39+S39+U39+W39+Y39 -> 177 | L39: LED TV 42" | M39: {=IF(ISBLANK(L39),"",XLOOKUP(L39, DeviceWattagesTbl[Device], DeviceWattagesTbl[Power]))} -> 57 | N39: Computer Small | O39: {=IF(ISBLANK(N39),"",XLOOKUP(N39, DeviceWattagesTbl[Device], DeviceWattagesTbl[Power]))} -> 120 | Q39: {=IF(ISBLANK(P39),"",XLOOKUP(P39, DeviceWattagesTbl[Device], DeviceWattagesTbl[Power]))} | S39: {=IF(ISBLANK(R39),"",XLOOKUP(R39, DeviceWattagesTbl[Device], DeviceWattagesTbl[Power]))} | U39: {=IF(ISBLANK(T39),"",XLOOKUP(T39, DeviceWattagesTbl[Device], DeviceWattagesTbl[Power]))} | W39: {=IF(ISBLANK(V39),"",XLOOKUP(V39, DeviceWattagesTbl[Device], DeviceWattagesTbl[Power]))} | Y39: {=IF(ISBLANK(X39),"",XLOOKUP(X39, DeviceWattagesTbl[Device], DeviceWattagesTbl[Power]))}
